Workbook

Sheet Operating model
A2: WACC | C2: =WACC!D17 -> 0.11828878
A3: TGR | C3: =DCF!$B$6 -> 0.03
A4: ROIC terminale | C4: =Estimates!O39*(1-O29)/(Estimates!N56+Estimates!N85+'Consolidated Balance Sheet'!C15+'Consolidated Balance Sheet'!C16-SUM(Estimates!$F$59:'Estimates'!N59)) -> 0.23020013
A7: Revenues | C7: 2024 | D7: 2025 | E7: 2026 | F7: =E7+1 -> 2027 | G7: =F7+1 -> 2028 | H7: =G7+1 -> 2029 | I7: =H7+1 -> 2030 | J7: =I7+1 -> 2031 | K7: =J7+1 -> 2032 | L7: =K7+1 -> 2033 | M7: =L7+1 -> 2034 | ... O7: =N7+1 -> 2036
A9: Datacenter & Communications | C9: ='Note 20 - Segment Results'!B6 -> 2631.369 | D9: ='Note 20 - Segment Results'!C6 -> 3755.164 | E9: ='Note 20 - Segment Results'!D6 -> 5274.629 | F9: =F17-F13 -> 8761.7546 | G9: =F9*(1+G10) -> 11931.656 | H9: =G9*(1+H10) -> 15082.251 | I9: =H9*(1+I10) -> 18174.113 | J9: =I9*(1+J10) -> 21263.712 | K9: =J9*(1+K10) -> 24283.159 | L9: =K9*(1+L10) -> 27051.439 | M9: =L9*(1+M10) -> 29377.863 | N9: =M9*(1+N10) -> 31081.779 | O9: =N9*(1+O10) -> 32014.232
A10: % growth | D10: =(D9/C9)-1 -> 0.42707617 | E10: =(E9/D9)-1 -> 0.40463346 | F10: =(F9/E9)-1 -> 0.66111295 | G10: =Estimates!K7 -> 0.36178843 | H10: =Estimates!K8 -> 0.26405347 | I10: =Estimates!K9 -> 0.205 | J10: =Estimates!K10 -> 0.17 | K10: =$J$10-($J$10-$C$3)*(K$7-$J$7)/5 -> 0.142 | L10: =$J$10-($J$10-$C$3)*(L$7-$J$7)/5 -> 0.114 | M10: =$J$10-($J$10-$C$3)*(M$7-$J$7)/5 -> 0.086 | N10: =$J$10-($J$10-$C$3)*(N$7-$J$7)/5 -> 0.058 | O10: =$J$10-($J$10-$C$3)*(O$7-$J$7)/5 -> 0.03
A11: % of sales | C11: =C9/C$17 -> 0.55895144 | D11: =D9/D$17 -> 0.64631492 | E11: =E9/E$17 -> 0.74100799 | F11: =F9/F$17 -> 0.83049806 | G11: =G9/G$17 -> 0.86291218 | H11: =H9/H$17 -> 0.88244041 | I11: =I9/I$17 -> 0.89598935 | J11: =J9/J$17 -> 0.90605769 | ... O11: =O9/O$17 -> 0.92405814
A13: Industrial | C13: ='Note 20 - Segment Results'!B7 -> 2076.319 | D13: ='Note 20 - Segment Results'!C7 -> 2054.951 | E13: ='Note 20 - Segment Results'!D7 -> 1843.552 | F13: =E13*(1+F14) -> 1788.2454 | G13: =F13*(1+G14) -> 1895.5402 | H13: =G13*(1+H14) -> 2009.2726 | I13: =H13*(1+I14) -> 2109.7362 | J13: =I13*(1+J14) -> 2204.6743 | K13: =J13*(1+K14) -> 2297.2707 | L13: =K13*(1+L14) -> 2386.8642 | M13: =L13*(1+M14) -> 2472.7913 | ... O13: =N13*(1+O14) -> 2631.0252
A14: % growth | D14: =(D13/C13)-1 -> -0.01029129 | E14: =(E13/D13)-1 -> -0.10287301 | F14: -0.03 | G14: =Estimates!K15 -> 0.06 | H14: =Estimates!K16 -> 0.06 | I14: =Estimates!K17 -> 0.05 | J14: =Estimates!K18 -> 0.045 | K14: =$J$14-($J$14-$C$3)*(K$7-$J$7)/5 -> 0.042 | L14: =$J$14-($J$14-$C$3)*(L$7-$J$7)/5 -> 0.039 | M14: =$J$14-($J$14-$C$3)*(M$7-$J$7)/5 -> 0.036 | N14: =$J$14-($J$14-$C$3)*(N$7-$J$7)/5 -> 0.033 | O14: =$J$14-($J$14-$C$3)*(O$7-$J$7)/5 -> 0.03
A15: % of sales | C15: =C13/C$17 -> 0.44104856 | D15: =D13/D$17 -> 0.35368508 | E15: =E13/E$17 -> 0.25899201 | F15: =F13/F$17 -> 0.16950194 | G15: =G13/G$17 -> 0.13708782 | H15: =H13/H$17 -> 0.11755959 | I15: =I13/I$17 -> 0.10401065 | J15: =J13/J$17 -> 0.093942307 | ... O15: =O13/O$17 -> 0.075941859
A17: Total revenue | C17: =C9+C13 -> 4707.688 | D17: =D9+D13 -> 5810.115 | E17: =E9+E13 -> 7118.181 | F17: 10550 | G17: =G9+G13 -> 13827.196 | H17: =H9+H13 -> 17091.524 | I17: =I9+I13 -> 20283.849 | J17: =J9+J13 -> 23468.386 | K17: =K9+K13 -> 26580.429 | L17: =L9+L13 -> 29438.303 | M17: =M9+M13 -> 31850.654 | N17: =N9+N13 -> 33636.172 | O17: =O9+O13 -> 34645.257
A18: % growth | D18: =(D17/C17)-1 -> 0.23417588 | E18: =(E17/D17)-1 -> 0.22513599 | F18: =(F17/E17)-1 -> 0.48212022 | G18: =(G17/F17)-1 -> 0.31063471 | H18: =(H17/G17)-1 -> 0.23608022 | I18: =(I17/H17)-1 -> 0.18677826 | J18: =(J17/I17)-1 -> 0.15699867 | K18: =(K17/J17)-1 -> 0.13260577 | ... O18: =(O17/N17)-1 -> 0.03
A20: EBIT | C20: 2024 | D20: 2025 | E20: 2026 | F20: =E20+1 -> 2027 | G20: =F20+1 -> 2028 | H20: =G20+1 -> 2029 | I20: =H20+1 -> 2030 | J20: =I20+1 -> 2031 | K20: =J20+1 -> 2032 | L20: =K20+1 -> 2033 | M20: =L20+1 -> 2034 | ... O20: =N20+1 -> 2036
A22: EBIT | C22: ='Consolidated Income Stmt'!B4-'Consolidated Income Stmt'!B6-'Consolidated Income Stmt'!B7-'Consolidated Income Stmt'!B8-'Consolidated Income Stmt'!B9-'Consolidated Income Stmt'!B10-'Consolidated Income Stmt'!B11 -> 96.121 | D22: ='Consolidated Income Stmt'!C4-'Consolidated Income Stmt'!C6-'Consolidated Income Stmt'!C7-'Consolidated Income Stmt'!C8-'Consolidated Income Stmt'!C9-'Consolidated Income Stmt'!C10-'Consolidated Income Stmt'!C11 -> 289.878 | E22: ='Consolidated Income Stmt'!D4-'Consolidated Income Stmt'!D6-'Consolidated Income Stmt'!D7-'Consolidated Income Stmt'!D8-'Consolidated Income Stmt'!D9-'Consolidated Income Stmt'!D10-'Consolidated Income Stmt'!D11 -> 897.861 | F22: =Estimates!F39 -> 1671.3 | G22: =Estimates!G39 -> 2465.7678 | H22: =Estimates!H39 -> 3366.9104 | I22: =Estimates!I39 -> 4361.3113 | J22: =Estimates!J39 -> 5460.3112 | K22: =Estimates!K39 -> 6627.3871 | L22: =Estimates!L39 -> 7830.5886 | M22: =Estimates!M39 -> 8472.274 | ... O22: =Estimates!O39 -> 9215.6384
A23: % growth | D23: =(D22/C22)-1 -> 2.0157614 | E23: =(E22/D22)-1 -> 2.0973754 | F23: =(F22/E22)-1 -> 0.86142398 | G23: =(G22/F22)-1 -> 0.4753592 | H23: =(H22/G22)-1 -> 0.36546124 | I23: =(I22/H22)-1 -> 0.29534524 | J23: =(J22/I22)-1 -> 0.25198839 | K23: =(K22/J22)-1 -> 0.21373799 | ... O23: =(O22/N22)-1 -> 0.03
A24: % of sales | C24: =C22/C$17 -> 0.020417878 | D24: =D22/D$17 -> 0.049891956 | E24: =E22/E$17 -> 0.1261363 | F24: =F22/F$17 -> 0.15841706 | G24: =G22/G$17 -> 0.17832739 | H24: =H22/H$17 -> 0.19699299 | I24: =I22/I$17 -> 0.21501399 | J24: =J22/J$17 -> 0.23266667 | ... O24: =O22/O$17 -> 0.266
A26: TAX RATE | C26: 2024 | D26: 2025 | E26: 2026 | F26: =E26+1 -> 2027 | G26: =F26+1 -> 2028 | H26: =G26+1 -> 2029 | I26: =H26+1 -> 2030 | J26: =I26+1 -> 2031 | K26: =J26+1 -> 2032 | L26: =K26+1 -> 2033 | M26: =L26+1 -> 2034 | ... O26: =N26+1 -> 2036
A28: Taxes | C28: 11.117 | D28: 64.124 | E28: 60.849 | F28: =F22*F29 -> 350.973 | G28: =G22*G29 -> 517.81124 | H28: =H22*H29 -> 707.05118 | I28: =I22*I29 -> 915.87538 | J28: =J22*J29 -> 1146.6653 | K28: =K22*K29 -> 1391.7513 | L28: =L22*L29 -> 1644.4236 | M28: =M22*M29 -> 1779.1775 | ... O28: =O22*O29 -> 1935.2841
A29: % tax rate | C29: ='Consolidated Income Stmt'!B16/'Consolidated Income Stmt'!B15 -> -0.075294452 | D29: ='Consolidated Income Stmt'!C16/'Consolidated Income Stmt'!C15 -> 0.6808592 | E29: ='Consolidated Income Stmt'!D16/'Consolidated Income Stmt'!D15 -> 0.071778496 | F29: 0.21 | G29: 0.21 | H29: 0.21 | I29: 0.21 | J29: 0.21 | K29: 0.21 | L29: 0.21 | M29: 0.21 | N29: 0.21 | O29: 0.21
A31: D&A | C31: 2024 | D31: 2025 | E31: 2026 | F31: =E31+1 -> 2027 | G31: =F31+1 -> 2028 | H31: =G31+1 -> 2029 | I31: =H31+1 -> 2030 | J31: =I31+1 -> 2031 | K31: =J31+1 -> 2032 | L31: =K31+1 -> 2033 | M31: =L31+1 -> 2034 | ... O31: =N31+1 -> 2036
A33: Datacenter & Communications | C33: ='Note 20 - D&A by Segment'!B5 -> 213.693 | D33: ='Note 20 - D&A by Segment'!C5 -> 209.293 | E33: ='Note 20 - D&A by Segment'!D5 -> 212.56
A34: % growth | D34: =(D33/C33)-1 -> -0.020590286 | E34: =(E33/D33)-1 -> 0.015609695
A35: % of D&A | C35: =C33/C$41 -> 0.38552285 | D35: =D33/D$41 -> 0.38145516 | E35: =E33/E$41 -> 0.41072809
A37: Industrial | C37: ='Note 20 - D&A by Segment'!B6 -> 340.601 | D37: ='Note 20 - D&A by Segment'!C6 -> 339.377 | E37: ='Note 20 - D&A by Segment'!D6 -> 304.96
A38: % growth | D38: =(D37/C37)-1 -> -0.0035936477 | E38: =(E37/D37)-1 -> -0.10141229
A39: % of D&A | C39: =C37/C$41 -> 0.61447715 | D39: =D37/D$41 -> 0.61854484 | E39: =E37/E$41 -> 0.58927191
A41: Total D&A | C41: =C33+C37 -> 554.294 | D41: =D33+D37 -> 548.67 | E41: =E33+E37 -> 517.52 | F41: =Estimates!F63 -> 663.16999 | G41: =Estimates!G63 -> 918.18537 | H41: =Estimates!H63 -> 1254.8459 | I41: =Estimates!I63 -> 1449.7772 | J41: =Estimates!J63 -> 1633.8241 | K41: =Estimates!K63 -> 1825.5778 | L41: =Estimates!L63 -> 2016.2431 | M41: =Estimates!M63 -> 2191.3362 | ... O41: =Estimates!O63 -> 2448.5266
A42: % growth | D42: =(D41/C41)-1 -> -0.01014624 | E42: =(E41/D41)-1 -> -0.056773653 | F42: =(F41/E41)-1 -> 0.28143837 | G42: =(G41/F41)-1 -> 0.38453999 | H42: =(H41/G41)-1 -> 0.3666586 | I42: =(I41/H41)-1 -> 0.15534278 | J42: =(J41/I41)-1 -> 0.1269484 | K42: =(K41/J41)-1 -> 0.11736499 | ... O42: =(O41/N41)-1 -> 0.046766539
A43: % of sales | C43: =C41/C$17 -> 0.1177423 | D43: =D41/D$17 -> 0.094433587 | E43: =E41/E$17 -> 0.072703967 | F43: =F41/F$17 -> 0.062859714 | G43: =G41/G$17 -> 0.066404306 | H43: =H41/H$17 -> 0.073419196 | I43: =I41/I$17 -> 0.071474462 | J43: =J41/J$17 -> 0.069618084 | ... O43: =O41/O$17 -> 0.070674223
A45: CAPEX | C45: 2024 | D45: 2025 | E45: 2026 | F45: =E45+1 -> 2027 | G45: =F45+1 -> 2028 | H45: =G45+1 -> 2029 | I45: =H45+1 -> 2030 | J45: =I45+1 -> 2031 | K45: =J45+1 -> 2032 | L45: =K45+1 -> 2033 | M45: =L45+1 -> 2034 | ... O45: =N45+1 -> 2036
A47: CapEx | C47: -346.816 | D47: -440.836 | E47: -1102.909 | F47: =Estimates!F45 -> -2637.5 | G47: =Estimates!G45 -> -3180.2551 | H47: =Estimates!H45 -> -2552.2826 | I47: =Estimates!I45 -> -2717.991 | J47: =Estimates!J45 -> -2909.8664 | K47: =Estimates!K45 -> -3070.4522 | L47: =Estimates!L45 -> -3140.0843 | M47: =Estimates!M45 -> -3103.0237 | ... O47: =Estimates!O45 -> -2878.4088
A48: % growth | D48: =(D47/C47)-1 -> 0.27109476 | E48: =(E47/D47)-1 -> 1.5018578 | F48: =(F47/E47)-1 -> 1.3914031 | G48: =(G47/F47)-1 -> 0.20578393 | H48: =(H47/G47)-1 -> -0.19745979 | I48: =(I47/H47)-1 -> 0.064925562 | J48: =(J47/I47)-1 -> 0.070594565 | K48: =(K47/J47)-1 -> 0.055186676 | ... O48: =(O47/N47)-1 -> -0.025037993
A49: % of sales | C49: =-C47/C$17 -> 0.073670133 | D49: =-D47/D$17 -> 0.075873885 | E49: =-E47/E$17 -> 0.15494253 | F49: =Estimates!F46 -> 0.25 | G49: =Estimates!G46 -> 0.23 | H49: =Estimates!H46 -> 0.14933031 | I49: =Estimates!I46 -> 0.13399779 | J49: =Estimates!J46 -> 0.1239909 | K49: =Estimates!K46 -> 0.11551552 | L49: =Estimates!L46 -> 0.10666662 | M49: =Estimates!M46 -> 0.097424175 | ... O49: =Estimates!O46 -> 0.083082333
A51: ΔNWC | C51: 2024 | D51: 2025 | E51: 2026 | F51: =E51+1 -> 2027 | G51: =F51+1 -> 2028 | H51: =G51+1 -> 2029 | I51: =H51+1 -> 2030 | J51: =I51+1 -> 2031 | K51: =J51+1 -> 2032 | L51: =K51+1 -> 2033 | M51: =L51+1 -> 2034 | ... O51: =N51+1 -> 2036
A53: NWC | C53: =Estimates!C85 -> 1448.723 | D53: =Estimates!D85 -> 1579.232 | E53: =Estimates!E85 -> 2584.818 | F53: =Estimates!F85 -> 3049.0945 | G53: =Estimates!G85 -> 3973.8983 | H53: =Estimates!H85 -> 4884.4297 | I53: =Estimates!I85 -> 5763.9474 | J53: =Estimates!J85 -> 6630.9443 | ... O53: =Estimates!O85 -> 9676.9424
A55: ΔNWC | D55: =D53-C53 -> 130.509 | E55: =E53-D53 -> 1005.586 | F55: =F53-E53 -> 464.27652 | G55: =G53-F53 -> 924.80377 | H55: =H53-G53 -> 910.5314 | I55: =I53-H53 -> 879.5177 | J55: =J53-I53 -> 866.99687 | K55: =K53-J53 -> 836.33584 | ... O55: =O53-N53 -> 281.85269
A56: % growth | E56: =(E55/D55)-1 -> 6.7051085 | F56: =(F55/E55)-1 -> -0.53830252 | G56: =(G55/F55)-1 -> 0.99192449 | H56: =(H55/G55)-1 -> -0.015432869 | I56: =(I55/H55)-1 -> -0.034061093 | J56: =(J55/I55)-1 -> -0.014236019 | K56: =(K55/J55)-1 -> -0.03536464 | L56: =(L55/K55)-1 -> -0.096915957 | ... O56: =(O55/N55)-1 -> -0.43485023
A57: % of sales | D57: =D55/D$17 -> 0.022462378 | E57: =E55/E$17 -> 0.14127008 | F57: =F55/F$17 -> 0.044007253 | G57: =G55/G$17 -> 0.066882957 | H57: =H55/H$17 -> 0.053273857 | I57: =I55/I$17 -> 0.043360494 | J57: =J55/J$17 -> 0.036943183 | K57: =K55/K$17 -> 0.031464346 | ... O57: =O55/O$17 -> 0.0081353903

Sheet WACC
A2: WACC
A4: Market Cap | D4: 57770.59
A5: % of Equity | D5: =D4/(D11+D4) -> 0.94717043
A6: Cost of Equity | D6: =D7+(D8*D9) -> 0.12201356
A7: Risk Free Rate | D7: 0.0468
A8: Beta | D8: =C30 -> 1.7016642
A9: Market Risk Premium | D9: 0.0442
A11: Debt | D11: ='Consolidated Balance Sheet'!C30+'Consolidated Balance Sheet'!C23 -> 3222.224
A12: % of Debt | D12: =D11/(D4+D11) -> 0.052829568
A13: Cost of Debt | D13: =D7+D14 -> 0.0652
A14: Spread BB | D14: 0.0184
A15: Tax Rate | D15: 0.21
A17: WACC | D17: =(D5*D6)+((D12*D13)*(1-D15)) -> 0.11828878
A21: BETA
B23: Levered Beta | C23: Market Cap | D23: Debt | E23: Tax rate | G23: Unlevered Beta
A25: LITE | B25: 1.9 | C25: 86936.96 | D25: 1461.8 | E25: 0.21 | G25: =B25/(1+(1-E25)*(D25/C25)) -> 1.8750923
A26: FN | B26: 1.62 | C26: 16521.93 | D26: =26.32+12.44 -> 38.76 | E26: 0.21 | G26: =B26/(1+(1-E26)*(D26/C26)) -> 1.6170032
A27: CIEN | B27: 1.42 | C27: 57716.12 | D27: =1021.1+157.9 -> 1179 | E27: 0.21 | G27: =B27/(1+(1-E27)*(D27/C27)) -> 1.3974483
A29: Average unlevered Beta | C29: =AVERAGE(G25:G27) -> 1.6298479
A30: Levered Beta | C30: =C29*(1+(1-D15)*(D11/D4)) -> 1.7016642
A34: Beta terminale | C34: 1.15
A35: Ke terminale | C35: =D7+C34*D9 -> 0.09763
A36: WACC terminale | C36: =(D5*C35)+((D12*D13)*(1-D15)) -> 0.095193395

Sheet Estimates
A2: REVENUES | C2: Q1% | D2: Q2% | E2: Q3% | F2: Q4% | G2: Q1 | H2: Q2 | I2: Q3 | J2: Q4 | K2: Annual
A4: D&C
A6: FY 2027 | J6: =3000*'Operating model'!F11 -> 2491.4942
A7: FY2028 | C7: 0.08 | D7: 0.07 | E7: 0.07 | F7: 0.065 | G7: =$J$6*(1+C7+Scenarios!$E$9) -> 2690.8137 | H7: =G7*(1+D7+Scenarios!$E$9) -> 2879.1707 | I7: =H7*(1+E7+Scenarios!$E$9) -> 3080.7126 | J7: =I7*(1+F7+Scenarios!$E$9) -> 3280.959 | K7: =(SUM(G7:J7)/'Operating model'!F9)-1 -> 0.36178843
A8: FY2029 | C8: 0.06 | D8: 0.055 | E8: 0.055 | F8: 0.05 | G8: =$J$7*(1+C8+Scenarios!$E$9) -> 3477.8165 | H8: =G8*(1+D8+Scenarios!$E$9) -> 3669.0964 | I8: =H8*(1+E8+Scenarios!$E$9) -> 3870.8967 | J8: =I8*(1+F8+Scenarios!$E$9) -> 4064.4415 | K8: =(SUM(G8:J8)/'Operating model'!G9)-1 -> 0.26405347
A9: FY2030 | K9: =Scenarios!$E$10 -> 0.205
A10: FY2031 | K10: =Scenarios!$E$11 -> 0.17
A12: Industrial
A14: FY2027
A15: FY2028 | K15: 0.06
A16: FY2029 | K16: 0.06
A17: FY2030 | K17: 0.05
A18: FY2031 | K18: 0.045
A21: EBIT | C21: 2024 | D21: 2025 | E21: 2026 | F21: =E21+1 -> 2027 | G21: =F21+1 -> 2028 | H21: =G21+1 -> 2029 | I21: =H21+1 -> 2030 | J21: =I21+1 -> 2031 | K21: =J21+1 -> 2032 | L21: =K21+1 -> 2033 | M21: =L21+1 -> 2034 | ... O21: =N21+1 -> 2036
A23: Revenues | C23: {='Consolidated Income Stmt'!B4:D4} -> 4707.688 | D23: 5810.115 | E23: 7118.181
A24: COGS | C24: {='Consolidated Income Stmt'!B6:D6} -> 3251.724 | D24: 3766.793 | E24: 4449.141
A25: % of revenues | C25: =C24/C23 -> 0.69072632 | D25: =D24/D23 -> 0.64831643 | E25: =E24/E23 -> 0.62503904
A26: % growth | D26: =D24/C24-1 -> 0.15839874 | E26: =E24/D24-1 -> 0.18114826
A27: Gross Profit | C27: =C23-C24 -> 1455.964 | D27: =D23-D24 -> 2043.322 | E27: =E23-E24 -> 2669.04 | F27: ='Operating model'!F17*Estimates!F28 -> 4072.3 | G27: ='Operating model'!G17*Estimates!G28 -> 5473.2651 | H27: ='Operating model'!H17*Estimates!H28 -> 6933.4614 | I27: ='Operating model'!I17*Estimates!I28 -> 8427.9392 | J27: ='Operating model'!J17*Estimates!J28 -> 9981.8869 | K27: ='Operating model'!K17*Estimates!K28 -> 11566.917 | L27: ='Operating model'!L17*Estimates!L28 -> 13100.045 | M27: ='Operating model'!M17*Estimates!M28 -> 14173.541 | ... O27: ='Operating model'!O17*Estimates!O28 -> 15417.139
A28: Gross Margin | C28: =C27/C23 -> 0.30927368 | D28: =D27/D23 -> 0.35168357 | E28: =E27/E23 -> 0.37496096 | F28: 0.386 | G28: =$F$28+($L$28-$F$28)*(G$21-$F$21)/($L$21-$F$21) -> 0.39583333 | H28: =$F$28+($L$28-$F$28)*(H$21-$F$21)/($L$21-$F$21) -> 0.40566667 | I28: =$F$28+($L$28-$F$28)*(I$21-$F$21)/($L$21-$F$21) -> 0.4155 | J28: =$F$28+($L$28-$F$28)*(J$21-$F$21)/($L$21-$F$21) -> 0.42533333 | K28: =$F$28+($L$28-$F$28)*(K$21-$F$21)/($L$21-$F$21) -> 0.43516667 | L28: =Scenarios!$E$12 -> 0.445 | M28: =L28 -> 0.445 | N28: =M28 -> 0.445 | O28: =N28 -> 0.445
A29: % growth | D29: =D27/C27-1 -> 0.40341519 | E29: =E27/D27-1 -> 0.30622584 | F29: =F27/E27-1 -> 0.52575458 | G29: =G27/F27-1 -> 0.34402307 | H29: =H27/G27-1 -> 0.26678706 | I29: =I27/H27-1 -> 0.21554569 | J29: =J27/I27-1 -> 0.18438051 | K29: =K27/J27-1 -> 0.15879062 | ... O29: =O27/N27-1 -> 0.03
A30: R&D | C30: {='Consolidated Income Stmt'!B7:D7} -> 478.788 | D30: 581.924 | E30: 722.952 | F30: ='Operating model'!F17*Estimates!F31 -> 1055 | G30: ='Operating model'!G17*Estimates!G31 -> 1352.7607 | H30: ='Operating model'!H17*Estimates!H31 -> 1635.0891 | I30: ='Operating model'!I17*Estimates!I31 -> 1896.5399 | J30: ='Operating model'!J17*Estimates!J31 -> 2143.4459 | K30: ='Operating model'!K17*Estimates!K31 -> 2370.0883 | L30: ='Operating model'!L17*Estimates!L31 -> 2561.1324 | M30: ='Operating model'!M17*Estimates!M31 -> 2771.0069 | ... O30: ='Operating model'!O17*Estimates!O31 -> 3014.1374
A31: % of revenues | C31: =C30/C23 -> 0.10170343 | D31: =D30/D23 -> 0.10015705 | E31: =E30/E23 -> 0.10156415 | F31: 0.1 | G31: =$F$31+($L$31-$F$31)*(G$21-$F$21)/($L$21-$F$21) -> 0.097833333 | H31: =$F$31+($L$31-$F$31)*(H$21-$F$21)/($L$21-$F$21) -> 0.095666667 | I31: =$F$31+($L$31-$F$31)*(I$21-$F$21)/($L$21-$F$21) -> 0.0935 | J31: =$F$31+($L$31-$F$31)*(J$21-$F$21)/($L$21-$F$21) -> 0.091333333 | K31: =$F$31+($L$31-$F$31)*(K$21-$F$21)/($L$21-$F$21) -> 0.089166667 | L31: 0.087 | M31: =L31 -> 0.087 | N31: =M31 -> 0.087 | O31: =N31 -> 0.087
A32: % growth | D32: =D30/C30-1 -> 0.21541058 | E32: =E30/D30-1 -> 0.2423478 | F32: =F30/E30-1 -> 0.45929467 | G32: =G30/F30-1 -> 0.28223762 | H32: =H30/G30-1 -> 0.20870536 | I32: =I30/H30-1 -> 0.15990001 | J32: =J30/I30-1 -> 0.13018765 | K32: =K30/J30-1 -> 0.10573738 | ... O32: =O30/N30-1 -> 0.03
A33: SG&A | C33: {='Consolidated Income Stmt'!B8:D8} -> 854.001 | D33: 926.451 | E33: 1044.566 | F33: ='Operating model'!F17*Estimates!F34 -> 1266 | G33: ='Operating model'!G17*Estimates!G34 -> 1594.7366 | H33: ='Operating model'!H17*Estimates!H34 -> 1891.462 | I33: ='Operating model'!I17*Estimates!I34 -> 2150.088 | J33: ='Operating model'!J17*Estimates!J34 -> 2378.1298 | K33: ='Operating model'!K17*Estimates!K34 -> 2569.4415 | L33: ='Operating model'!L17*Estimates!L34 -> 2708.3239 | M33: ='Operating model'!M17*Estimates!M34 -> 2930.2602 | ... O33: ='Operating model'!O17*Estimates!O34 -> 3187.3637
A34: % of revenues | C34: =C33/C23 -> 0.18140561 | D34: =D33/D23 -> 0.15945485 | E34: =E33/E23 -> 0.1467462 | F34: 0.12 | G34: =$F$34+($L$34-$F$34)*(G$21-$F$21)/($L$21-$F$21) -> 0.11533333 | H34: =$F$34+($L$34-$F$34)*(H$21-$F$21)/($L$21-$F$21) -> 0.11066667 | I34: =$F$34+($L$34-$F$34)*(I$21-$F$21)/($L$21-$F$21) -> 0.106 | J34: =$F$34+($L$34-$F$34)*(J$21-$F$21)/($L$21-$F$21) -> 0.10133333 | K34: =$F$34+($L$34-$F$34)*(K$21-$F$21)/($L$21-$F$21) -> 0.096666667 | L34: =Scenarios!$E$13 -> 0.092 | M34: =L34 -> 0.092 | N34: =M34 -> 0.092 | O34: =N34 -> 0.092
A35: % growth | D35: =D33/C33-1 -> 0.084835966 | E35: =E33/D33-1 -> 0.1274919 | F35: =F33/E33-1 -> 0.2119866 | G35: =G33/F33-1 -> 0.25966558 | H35: =H33/G33-1 -> 0.18606542 | I35: =I33/H33-1 -> 0.1367334 | J35: =J33/I33-1 -> 0.10606162 | K35: =K33/J33-1 -> 0.080446293 | ... O35: =O33/N33-1 -> 0.03
A36: Altri costi operativi | C36: =SUM('Consolidated Income Stmt'!B9:B11) -> 27.054 | D36: =SUM('Consolidated Income Stmt'!C9:C11) -> 245.069 | E36: =SUM('Consolidated Income Stmt'!D9:D11) -> 3.661 | F36: 80 | G36: 60 | H36: 40 | I36: 20 | J36: 0 | K36: =J36 -> 0 | L36: =K36 -> 0 | M36: =L36 -> 0 | N36: =M36 -> 0 | O36: =N36 -> 0
A37: % of revenues | C37: =C36/C23 -> 0.00574677 | D37: =D36/D23 -> 0.042179716 | E37: =E36/E23 -> 0.00051431679
A38: % growth | D38: =D36/C36-1 -> 8.0585126 | E38: =E36/D36-1 -> -0.98506135 | F38: =F36/E36-1 -> 20.851953 | G38: =G36/F36-1 -> -0.25 | H38: =H36/G36-1 -> -0.33333333 | I38: =I36/H36-1 -> -0.5 | J38: =J36/I36-1 -> -1
A39: EBIT | C39: ='Operating model'!C22 -> 96.121 | D39: ='Operating model'!D22 -> 289.878 | E39: ='Operating model'!E22 -> 897.861 | F39: =F27-F30-F33-F36 -> 1671.3 | G39: =G27-G30-G33-G36 -> 2465.7678 | H39: =H27-H30-H33-H36 -> 3366.9104 | I39: =I27-I30-I33-I36 -> 4361.3113 | J39: =J27-J30-J33-J36 -> 5460.3112 | K39: =K27-K30-K33-K36 -> 6627.3871 | L39: =L27-L30-L33-L36 -> 7830.5886 | M39: =M27-M30-M33-M36 -> 8472.274 | ... O39: =O27-O30-O33-O36 -> 9215.6384
A40: EBIT Margin | C40: =C39/C23 -> 0.020417878 | D40: =D39/D23 -> 0.049891956 | E40: =E39/E23 -> 0.1261363 | F40: =F39/'Operating model'!F17 -> 0.15841706 | G40: =G39/'Operating model'!G17 -> 0.17832739 | H40: =H39/'Operating model'!H17 -> 0.19699299 | I40: =I39/'Operating model'!I17 -> 0.21501399 | J40: =J39/'Operating model'!J17 -> 0.23266667 | K40: =K39/'Operating model'!K17 -> 0.24933333 | L40: =L39/'Operating model'!L17 -> 0.266 | M40: =M39/'Operating model'!M17 -> 0.266 | ... O40: =O39/'Operating model'!O17 -> 0.266
A43: CapEx | C43: 2024 | D43: 2025 | E43: 2026 | F43: =E43+1 -> 2027 | G43: =F43+1 -> 2028 | H43: =G43+1 -> 2029 | I43: =H43+1 -> 2030 | J43: =I43+1 -> 2031 | K43: =J43+1 -> 2032 | L43: =K43+1 -> 2033 | M43: =L43+1 -> 2034 | ... O43: =N43+1 -> 2036
A45: CapEx | C45: ='Operating model'!C47 -> -346.816 | D45: ='Operating model'!D47 -> -440.836 | E45: ='Operating model'!E47 -> -1102.909 | F45: =-'Operating model'!F17*Estimates!F46 -> -2637.5 | G45: =-'Operating model'!G17*Estimates!G46 -> -3180.2551 | H45: =-(H55 + ('Operating model'!H17-'Operating model'!G17)/$O$48) -> -2552.2826 | I45: =-(I55 + ('Operating model'!I17-'Operating model'!H17)/$O$48) -> -2717.991 | J45: =-(J55 + ('Operating model'!J17-'Operating model'!I17)/$O$48) -> -2909.8664 | K45: =-(K55 + ('Operating model'!K17-'Operating model'!J17)/$O$48) -> -3070.4522 | L45: =-(L55 + ('Operating model'!L17-'Operating model'!K17)/$O$48) -> -3140.0843 | M45: =-(M55 + ('Operating model'!M17-'Operating model'!L17)/$O$48) -> -3103.0237 | N45: =-(N55 + ('Operating model'!N17-'Operating model'!M17)/$O$48) -> -2952.3292 | O45: =-(O50-O86+O55) -> -2878.4088
A46: % of sales | C46: ='Operating model'!C49 -> 0.073670133 | D46: ='Operating model'!D49 -> 0.075873885 | E46: ='Operating model'!E49 -> 0.15494253 | F46: 0.25 | G46: 0.23 | H46: =-H45/'Operating model'!H17 -> 0.14933031 | I46: =-I45/'Operating model'!I17 -> 0.13399779 | J46: =-J45/'Operating model'!J17 -> 0.1239909 | K46: =-K45/'Operating model'!K17 -> 0.11551552 | L46: =-L45/'Operating model'!L17 -> 0.10666662 | M46: =-M45/'Operating model'!M17 -> 0.097424175 | N46: =-N45/'Operating model'!N17 -> 0.087772449 | O46: =-O45/'Operating model'!O17 -> 0.083082333
A48: CapEx efficiency | O48: 2.1
A49: Reinvestment rate | O49: ='Operating model'!C3/'Operating model'!C4 -> 0.13032138
A50: Reinvestimento | O50: =O49*DCF!O16 -> 948.78586
A53: D&A | C53: 2024 | D53: 2025 | E53: 2026 | F53: =E53+1 -> 2027 | G53: =F53+1 -> 2028 | H53: =G53+1 -> 2029 | I53: =H53+1 -> 2030 | J53: =I53+1 -> 2031 | K53: =J53+1 -> 2032 | L53: =K53+1 -> 2033 | M53: =L53+1 -> 2034 | ... O53: =N53+1 -> 2036
A55: Depreciation | C55: ='Consolidated Cash Flow'!B7 -> 271.601 | D55: ='Consolidated Cash Flow'!C7 -> 250.81 | E55: ='Consolidated Cash Flow'!D7 -> 241.561 | F55: =$E$57*E56 -> 385.89699 | G55: =$E$57*F56 -> 675.58937 | H55: =$E$57*G56 -> 997.84093 | I55: =$E$57*H56 -> 1197.8362 | J55: =$E$57*I56 -> 1393.4201 | K55: =$E$57*J56 -> 1588.5268 | L55: =$E$57*K56 -> 1779.1921 | M55: =$E$57*L56 -> 1954.2852 | ... O55: =$E$57*N56 -> 2211.4756
...

Sheet Scenarios
A2: Scenarios
A4: Scenario | B4: Base
A5: Switch | B5: =IF($B$6<>"",$B$6,IFERROR(MATCH($B$4,$B$8:$D$8,0),2)) -> 2
A6: Override
A8: Driver | B8: Bear | C8: Base | D8: Bull | E8: Attivo
A9: D&C Δ trim. FY28-29 | B9: -0.015 | C9: 0 | D9: 0.015 | E9: {=INDEX(B9:D9,$B$5)} -> 0
A10: D&C crescita FY2030 | B10: 0.13 | C10: 0.205 | D10: 0.26 | E10: {=INDEX(B10:D10,$B$5)} -> 0.205
A11: D&C crescita FY2031 | B11: 0.09 | C11: 0.17 | D11: 0.22 | E11: {=INDEX(B11:D11,$B$5)} -> 0.17
A12: Gross margin terminale | B12: 0.415 | C12: 0.445 | D12: 0.465 | E12: {=INDEX(B12:D12,$B$5)} -> 0.445
A13: SG&A terminale (% ricavi) | B13: 0.102 | C13: 0.092 | D13: 0.087 | E13: {=INDEX(B13:D13,$B$5)} -> 0.092
A14: TGR | B14: 0.025 | C14: 0.03 | D14: 0.035 | E14: {=INDEX(B14:D14,$B$5)} -> 0.03
A18: Scenarios | B18: Target price | C18: ROIC
B20: =DCF!$C$45 -> 241.20469 | C20: ='Operating model'!$C$4 -> 0.23020013
A21: 1 | B21: 141.90743 | C21: 0.17817015
A22: 2 | B22: 241.20469 | C22: 0.23020013
A23: 3 | B23: 357.40598 | C23: 0.2666095
A28: Probabilità bear case | C28: 0.15
A29: Prezzo di mercato | C29: 295
A31: Probabilità bull case implicita | C31: =($C$29-$B$21*C28-$B$22*(1-C28))/($B$23-$B$22) -> 0.59112856
A32: Probabilità base case implicita | C32: =1-C28-C31 -> 0.25887144

Sheet DCF
A2: DCF
A4: WACC | B4: =WACC!D17 -> 0.11828878 | F4: =WACC!$D$17 -> 0.11828878 | G4: =$F$4+($B$5-$F$4)*(G8-$F$8)/9 -> 0.11572263 | H4: =$F$4+($B$5-$F$4)*(H8-$F$8)/9 -> 0.11315647 | I4: =$F$4+($B$5-$F$4)*(I8-$F$8)/9 -> 0.11059032 | J4: =$F$4+($B$5-$F$4)*(J8-$F$8)/9 -> 0.10802416 | K4: =$F$4+($B$5-$F$4)*(K8-$F$8)/9 -> 0.10545801 | L4: =$F$4+($B$5-$F$4)*(L8-$F$8)/9 -> 0.10289186 | M4: =$F$4+($B$5-$F$4)*(M8-$F$8)/9 -> 0.1003257 | N4: =$F$4+($B$5-$F$4)*(N8-$F$8)/9 -> 0.097759549 | O4: =$F$4+($B$5-$F$4)*(O8-$F$8)/9 -> 0.095193395
A5: WACC terminale | B5: =WACC!C36 -> 0.095193395
A6: TGR | B6: =Scenarios!E14 -> 0.03
C8: 2024 | D8: 2025 | E8: 2026 | F8: =E8+1 -> 2027 | G8: =F8+1 -> 2028 | H8: =G8+1 -> 2029 | I8: =H8+1 -> 2030 | J8: =I8+1 -> 2031 | K8: =J8+1 -> 2032 | L8: =K8+1 -> 2033 | M8: =L8+1 -> 2034 | ... O8: =N8+1 -> 2036
A10: Revenues | C10: ='Operating model'!C17 -> 4707.688 | D10: ='Operating model'!D17 -> 5810.115 | E10: ='Operating model'!E17 -> 7118.181 | F10: ='Operating model'!F17 -> 10550 | G10: ='Operating model'!G17 -> 13827.196 | H10: ='Operating model'!H17 -> 17091.524 | I10: ='Operating model'!I17 -> 20283.849 | J10: ='Operating model'!J17 -> 23468.386 | ... O10: ='Operating model'!O17 -> 34645.257
A12: EBIT | C12: ='Operating model'!C22 -> 96.121 | D12: ='Operating model'!D22 -> 289.878 | E12: ='Operating model'!E22 -> 897.861 | F12: ='Operating model'!F22 -> 1671.3 | G12: ='Operating model'!G22 -> 2465.7678 | H12: ='Operating model'!H22 -> 3366.9104 | I12: ='Operating model'!I22 -> 4361.3113 | J12: ='Operating model'!J22 -> 5460.3112 | ... O12: ='Operating model'!O22 -> 9215.6384
A14: Tax rate | C14: ='Operating model'!C29 -> -0.075294452 | D14: ='Operating model'!D29 -> 0.6808592 | E14: ='Operating model'!E29 -> 0.071778496 | F14: ='Operating model'!F29 -> 0.21 | G14: ='Operating model'!G29 -> 0.21 | H14: ='Operating model'!H29 -> 0.21 | I14: ='Operating model'!I29 -> 0.21 | J14: ='Operating model'!J29 -> 0.21 | ... O14: ='Operating model'!O29 -> 0.21
A16: NOPAT | C16: =C12*(1-C14) -> 103.35838 | D16: =D12*(1-D14) -> 92.511898 | E16: =E12*(1-E14) -> 833.41389 | F16: =F12*(1-F14) -> 1320.327 | G16: =G12*(1-G14) -> 1947.9566 | H16: =H12*(1-H14) -> 2659.8592 | I16: =I12*(1-I14) -> 3445.436 | J16: =J12*(1-J14) -> 4313.6458 | ... O16: =O12*(1-O14) -> 7280.3544
A18: D&A | C18: ='Operating model'!C41 -> 554.294 | D18: ='Operating model'!D41 -> 548.67 | E18: ='Operating model'!E41 -> 517.52 | F18: ='Operating model'!F41 -> 663.16999 | G18: ='Operating model'!G41 -> 918.18537 | H18: ='Operating model'!H41 -> 1254.8459 | I18: ='Operating model'!I41 -> 1449.7772 | J18: ='Operating model'!J41 -> 1633.8241 | ... O18: ='Operating model'!O41 -> 2448.5266
A20: CapEx | C20: ='Operating model'!C47 -> -346.816 | D20: ='Operating model'!D47 -> -440.836 | E20: ='Operating model'!E47 -> -1102.909 | F20: ='Operating model'!F47 -> -2637.5 | G20: ='Operating model'!G47 -> -3180.2551 | H20: ='Operating model'!H47 -> -2552.2826 | I20: ='Operating model'!I47 -> -2717.991 | J20: ='Operating model'!J47 -> -2909.8664 | ... O20: ='Operating model'!O47 -> -2878.4088
A22: ΔNWC | D22: ='Operating model'!D55 -> 130.509 | E22: ='Operating model'!E55 -> 1005.586 | F22: ='Operating model'!F55 -> 464.27652 | G22: ='Operating model'!G55 -> 924.80377 | H22: ='Operating model'!H55 -> 910.5314 | I22: ='Operating model'!I55 -> 879.5177 | J22: ='Operating model'!J55 -> 866.99687 | K22: ='Operating model'!K55 -> 836.33584 | ... O22: ='Operating model'!O55 -> 281.85269
A24: FCFF | D24: =D16+D18+D20-D22 -> 69.836898 | E24: =E16+E18+E20-E22 -> -757.56111 | F24: =F16+F18+F20-F22 -> -1118.2795 | G24: =G16+G18+G20-G22 -> -1238.9169 | H24: =H16+H18+H20-H22 -> 451.89113 | I24: =I16+I18+I20-I22 -> 1297.7044 | J24: =J16+J18+J20-J22 -> 2170.6066 | K24: =K16+K18+K20-K22 -> 3154.4255 | ... O24: =O16+O18+O20-O22 -> 6568.6195
A25: PV of FCFF | F25: =F24/F27 -> -999.99173 | G25: =G24/G27 -> -992.96052 | H25: =H24/H27 -> 325.36242 | I25: =I24/I27 -> 841.3089 | J25: =J24/J27 -> 1270.023 | K25: =K24/K27 -> 1669.5848 | L25: =L24/L27 -> 2066.9711 | M25: =M24/M27 -> 2227.6715 | ... O25: =O24/O27 -> 2382.9234
A27: Discount factor | F27: =1+F4 -> 1.1182888 | G27: =F27*(1+G4) -> 1.2477001 | H27: =G27*(1+H4) -> 1.3888854 | I27: =H27*(1+I4) -> 1.5424827 | J27: =I27*(1+J4) -> 1.7091081 | K27: =J27*(1+K4) -> 1.8893473 | L27: =K27*(1+L4) -> 2.0837457 | M27: =L27*(1+M4) -> 2.292799 | N27: =M27*(1+N4) -> 2.516942 | O27: =N27*(1+O4) -> 2.7565382
A31: Terminal value | C31: =(O24*(1+B6))/(B5-B6) -> 103778.58 | R31: Sensitivity Table (base case)
A32: PV of Terminal value | C32: =C31/O27 -> 37648.157
A33: Sum of PV FCFF | C33: =SUM(F25:O25) -> 11157.411 | T33: TGR
S34: =C45 -> 241.20469 | T34: 0.025 | U34: 0.0275 | V34: 0.03 | W34: 0.0325 | X34: 0.035
A35: Enterprise value | C35: =C32+C33 -> 48805.567 | R35: WACC Terminale | S35: 0.0852 | T35: 269.98754 | U35: 278.77613 | V35: 288.3596 | W35: 298.85106 | X35: 310.38617
S36: 0.0902 | T36: 247.74152 | U36: 254.97693 | V36: 262.81223 | W36: 271.32537 | X36: 280.60847
A37: Cash | C37: ='Consolidated Balance Sheet'!C6+'Consolidated Balance Sheet'!C8 -> 1987.018 | S37: 0.0952 | T37: 228.66087 | U37: 234.68893 | V37: 241.1783 | W37: 248.18415 | X37: 255.77085
A38: Debt | C38: ='Consolidated Balance Sheet'!C23+'Consolidated Balance Sheet'!C30 -> 3222.224 | S38: 0.1002 | T38: 212.11432 | U38: 217.18779 | V38: 222.62173 | W38: 228.4561 | X38: 234.73695
A39: NCI | C39: ='Consolidated Balance Sheet'!C44 -> 334.705 | S39: 0.1052 | T39: 197.62801 | U39: 201.93561 | V39: 206.52883 | W39: 211.43712 | X39: 216.69416
A41: Equity Value | C41: =C35+C37-C38-C39 -> 47235.656
A43: Shares outstanding | C43: 195.83225
A45: Implied share price | C45: =C41/C43 -> 241.20469

Sheet Cross-check
A2: Market cap | C2: =WACC!D4 -> 57770.59
A4: Debt | C4: =DCF!C38 -> 3222.224
A5: Cash | C5: =DCF!C37 -> 1987.018
A6: NCI | C6: =DCF!C39 -> 334.705
A8: Enterprise value | C8: =C2+C4+C6-C5 -> 59340.501
B10: 2026 | C10: 2027 | D10: 2028
A12: COHR
A13: EV | B13: =C8 -> 59340.501
A14: EBITDA consensus | C14: 2845.1 | D14: 4140.07
A15: EBITDA | C15: =Estimates!F39+Estimates!F63 -> 2334.47 | D15: =Estimates!G39+Estimates!G63 -> 3383.9532
A17: EV/EBITDA consensus | C17: =$B$13/C14 -> 20.857088 | D17: =$B$13/D14 -> 14.333212
A18: EV/EBITDA | C18: =$B$13/C15 -> 25.419261 | D18: =$B$13/D15 -> 17.535852
A20: LITE
A21: EV | B21: 82929.85
A22: EBITDA consensus | C22: 2782.78 | D22: 4396.67
A24: EV/EBITDA consensus | C24: =$B$21/C22 -> 29.80108 | D24: =$B$21/D22 -> 18.861968
A26: FN
A27: EV | B27: 16461.15
A28: EBITDA consensus | C28: 773.6 | D28: 944.63
A30: EV/EBITDA consensus | C30: =$B$27/C28 -> 21.278632 | D30: =$B$27/D28 -> 17.426029
A32: CIEN
A33: EV | B33: 79068.2
A34: EBITDA consensus | C34: 1989.95 | D34: 2852.84
A36: EV/EBITDA consensus | C36: =$B$33/C34 -> 39.733762 | D36: =$B$33/D34 -> 27.71561
A40: Mean | C40: =AVERAGE(C24,C30,C36) -> 30.271158 | D40: =AVERAGE(D24,D30,D36) -> 21.334536
A41: Median | C41: =MEDIAN(C24,C30,C36) -> 29.80108 | D41: =MEDIAN(D24,D30,D36) -> 18.861968
A45: DCF cross-check | C45: =DCF!C35/'Cross-check'!D15 -> 14.422648

Sheet Comps
A2: Comps
A4: Peers | C4: Enterprise value | E4: EBITDA 2027 | I4: EV/EBITDA 2027
A6: COHR | C6: =I25*E6 -> 80392.835 | E6: ='Cross-check'!C14 -> 2845.1
C7: =I25*E7 -> 65964.17 | E7: ='Cross-check'!C15 -> 2334.47
A9: LITE | C9: ='Cross-check'!B21 -> 82929.85 | E9: ='Cross-check'!C22 -> 2782.78 | I9: =C9/E9 -> 29.80108
A11: FN | C11: ='Cross-check'!B27 -> 16461.15 | E11: ='Cross-check'!C28 -> 773.6 | I11: =C11/E11 -> 21.278632
A13: CIEN | C13: ='Cross-check'!B33 -> 79068.2 | E13: ='Cross-check'!C34 -> 1989.95 | I13: =C13/E13 -> 39.733762
A15: IPGP | C15: 2272.84 | E15: 89.91 | I15: =C15/E15 -> 25.279057
A17: MKSI | C17: 14602.05 | E17: 907 | I17: =C17/E17 -> 16.099283
A19: Mean_D&C | I19: =AVERAGE(I9,I11,I13) -> 30.271158
A20: Median_D&C | I20: =MEDIAN(I9,I11,I13) -> 29.80108
A22: Mean_Industrial | I22: =AVERAGE(I15,I17) -> 20.68917
A23: Median_Industrial | I23: =MEDIAN(I15,I17) -> 20.68917
A25: Target_median | I25: =('Operating model'!F11*Comps!I20)+('Operating model'!F15*Comps!I23) -> 28.256594
A29: Cash | C29: =DCF!C37 -> 1987.018
A30: Debt | C30: =DCF!C38 -> 3222.224
A31: NCI | C31: =DCF!C39 -> 334.705
A33: Equity value | C33: =C6+C29-C30-C31 -> 78822.924 | D33: =C7+C29-C30-C31 -> 64394.259
A34: Shares outstanding | C34: =DCF!C43 -> 195.83225 | D34: =DCF!C43 -> 195.83225
A36: Target price | C36: =C33/C34 -> 402.50227 | D36: =D33/D34 -> 328.82357

Sheet Consolidated Balance Sheet
A1: Coherent Corp. and Subsidiaries - Consolidated Balance Sheets ($ in millions)
A3: June 30, | B3: 2025 | C3: 2026
A4: Assets
A5: Current Assets
A6: Cash and cash equivalents | B6: 909.2 | C6: 1162.018
A7: Restricted cash, current | B7: 8.897 | C7: 35.156
A8: Short-term investments | B8: — | C8: 825
A9: Accounts receivable - less allowance for doubtful accounts of $ 13,193 at June 30, 2026 and $ 12,189 at June 30, 2025 | B9: 964.051 | C9: 1343.278
A10: Inventories | B10: 1437.636 | C10: 2581.043
A11: Prepaid and refundable income taxes | B11: 55.773 | C11: 78.892
A12: Prepaid and other current assets | B12: 551.597 | C12: 900.112
A13: Total Current Assets | B13: 3927.154 | C13: 6925.499
A14: Property, plant & equipment, net | B14: 1877.507 | C14: 2999.343
A15: Goodwill | B15: 4471.084 | C15: 4375.597
A16: Other intangible assets, net | B16: 3204.747 | C16: 2884.474
A17: Deferred income taxes | B17: 53.407 | C17: 69.434
A18: Restricted cash, non-current | B18: 714.816 | C18: 571.222
A19: Other assets | B19: 662.221 | C19: 474.283
A20: Total Assets | B20: 14910.936 | C20: 18299.852
A21: Liabilities, Mezzanine Equity and Shareholders' Equity
A22: Current Liabilities
A23: Current portion of long-term debt | B23: 188.306 | C23: 7.916
A24: Accounts payable | B24: 846.984 | C24: 1905.357
A25: Accrued compensation and benefits | B25: 258.65 | C25: 358.047
A26: Operating lease current liabilities | B26: 41.575 | C26: 61.371
A27: Accrued income taxes payable | B27: 123.762 | C27: 173.248
A28: Other accrued liabilities | B28: 335.564 | C28: 347.99
A29: Total Current Liabilities | B29: 1794.841 | C29: 2853.929
A30: Long-term debt | B30: 3498.615 | C30: 3214.308
A31: Deferred income taxes | B31: 711.717 | C31: 540.61
A32: Operating lease liabilities | B32: 165.162 | C32: 254.839
A33: Other liabilities | B33: 259.318 | C33: 197.966
A34: Total Liabilities | B34: 6429.653 | C34: 7061.652
A35: Mezzanine Equity
A36: Series B redeemable convertible preferred stock, no par value, 5 % cumulative; issued - 0 and 215,000 shares at June 30, 2026 and June 30, 2025, respectively; redemption value - $ 0 and $ 2,540,110 , respectively | B36: 2483.261 | C36: —
A37: Shareholders' Equity
A38: Common stock, no par value; authorized - 300,000,000 shares; issued - 212,615,894 shares at June 30, 2026; 171,849,325 shares at June 30, 2025 | B38: 5056.168 | C38: 9790.596
A39: Accumulated other comprehensive income (AOCI) | B39: 372.037 | C39: 204.112
A40: Retained earnings | B40: 584.374 | C40: 1354.27
B41: 6012.579 | C41: 11348.978
...

Sheet Consolidated Income Stmt
A1: Coherent Corp. and Subsidiaries - Consolidated Statements of Earnings (Loss) ($ in millions, except per share data)
A3: Year Ended June 30, | B3: 2024 | C3: 2025 | D3: 2026
A4: Revenues | B4: 4707.688 | C4: 5810.115 | D4: 7118.181
A5: Costs, Expenses and Other Expense
A6: Cost of goods sold | B6: 3251.724 | C6: 3766.793 | D6: 4449.141
A7: Research and development | B7: 478.788 | C7: 581.924 | D7: 722.952
A8: Selling, general and administrative | B8: 854.001 | C8: 926.451 | D8: 1044.566
A9: Restructuring charges | B9: 27.054 | C9: 160.081 | D9: 63.39
A10: Impairment of assets held-for-sale | C10: 84.988 | D10: 64.404
A11: Gain on sale of business | D11: -124.133
A12: Interest expense | B12: 288.475 | C12: 243.251 | D12: 190.267
A13: Other income, net | B13: -44.707 | C13: -47.554 | D13: -140.139
A14: Total Costs, Expenses and Other Expense | B14: 4855.335 | C14: 5715.934 | D14: 6270.448
A15: Earnings (Loss) Before Income Taxes | B15: -147.647 | C15: 94.181 | D15: 847.733
A16: Income Tax Expense | B16: 11.117 | C16: 64.124 | D16: 60.849
A17: Net Earnings (Loss) | B17: -158.764 | C17: 30.057 | D17: 786.884
A18: Net Loss Attributable to Noncontrolling Interests | B18: -2.61 | C18: -19.307 | D18: -18.114
A19: Net Earnings (Loss) Attributable to Coherent Corp. | B19: -156.154 | C19: 49.364 | D19: 804.998
A20: Less: Dividends on Preferred Stock | B20: 123.357 | C20: 129.926 | D20: 35.102
A21: Net Earnings (Loss) Available to the Common Shareholders | B21: -279.511 | C21: -80.562 | D21: 769.896
A22: Basic Earnings (Loss) Per Share | B22: -1.84 | C22: -0.52 | D22: 4.34
A23: Diluted Earnings (Loss) Per Share | B23: -1.84 | C23: -0.52 | D23: 4.12
A26: Fonte: Coherent Corp., Form 10-K FY2026 (SEC EDGAR) - https://www.sec.gov/Archives/edgar/data/820318/000082031826000020/iivi-20260630.htm

Sheet Consolidated Cash Flow
A1: Coherent Corp. and Subsidiaries - Consolidated Statements of Cash Flows ($ in millions)
A3: Year Ended June 30, | B3: 2024 | C3: 2025 | D3: 2026
A4: Cash Flows from Operating Activities
A5: Net earnings (loss) | B5: -158.764 | C5: 30.057 | D5: 786.884
A6: Adjustments to reconcile net earnings (loss) to net cash provided by operating activities:
A7: Depreciation | B7: 271.601 | C7: 250.81 | D7: 241.561
A8: Amortization | B8: 288.16 | C8: 302.788 | D8: 280.334
A9: Share-based compensation expense | B9: 126.049 | C9: 160.239 | D9: 186.468
A10: Non-cash restructuring and impairment charges | B10: 16.557 | C10: 140.912 | D10: 87.563
A11: Amortization of debt issuance costs | B11: 17.652 | C11: 19.774 | D11: 17.56
A12: Loss on disposals of property, plant & equipment | B12: 0.758 | C12: 0.782 | D12: 0.599
A13: Unrealized losses (gains) on foreign currency remeasurements and transactions | B13: -10.556 | C13: 33.122 | D13: -24.792
A14: Loss (earnings) from equity investments | B14: 0.051 | C14: -1.316 | D14: -0.69
A15: Deferred income taxes | B15: -112.096 | C15: -95.434 | D15: -198.732
A16: Gain on sale of business | B16: — | C16: — | D16: -124.133
A17: Gain on sale of equity investment | B17: — | C17: — | D17: -73.998
A18: Loss on debt extinguishment | B18: 1.978 | C18: — | D18: 3.056
A19: Increase (decrease) in cash from changes in:
A20: Accounts receivable | B20: 60.581 | C20: -170.444 | D20: -367.631
A21: Inventories | B21: -23.196 | C21: -202.728 | D21: -1183
A22: Accounts payable | B22: 205.044 | C22: 217.357 | D22: 748.533
A23: Contract liabilities | B23: -72.818 | C23: 3.182 | D23: -9.307
A24: Income taxes | B24: 12.251 | C24: -22.118 | D24: 18.175
A25: Accrued compensation and benefits | B25: 36.894 | C25: 62.96 | D25: 99.397
A26: Other operating net assets (liabilities) | B26: -114.415 | C26: -96.343 | D26: -408.333
A27: Net cash provided by operating activities | B27: 545.731 | C27: 633.6 | D27: 79.514
A28: Cash Flows from Investing Activities
A29: Additions to property, plant & equipment | B29: -346.816 | C29: -440.836 | D29: -1102.909
A30: Purchases of intangible assets | B30: — | C30: — | D30: -7.174
A31: Proceeds from sale of equity investment | B31: — | C31: — | D31: 89.384
A32: Proceeds from the sale of business, net of fees | B32: — | C32: 27 | D32: 436.992
A33: Purchases of short-term investments | B33: — | C33: — | D33: -1025
A34: Proceeds from sales/maturities of short-term investments | B34: — | C34: — | D34: 200
A35: Other investing activities | B35: -3.897 | C35: -0.379 | D35: -5.017
A36: Net cash used in investing activities | B36: -350.713 | C36: -414.215 | D36: -1413.724
A37: Cash Flows from Financing Activities
A38: Sale of shares to noncontrolling interests | B38: 1000 | C38: — | D38: —
A39: Proceeds from borrowings of Term A Facility | B39: — | C39: — | D39: 1250
A40: Proceeds from borrowings of Term B Facility | B40: — | C40: — | D40: 3.267
A41: Proceeds from borrowings of revolving credit facilities | B41: 18.966 | C41: 53.729 | D41: 640.075
...

Sheet Note 20 - Segment Results
A1: Note 20. Segment and Geographic Reporting - Segment results and reconciliation to earnings (loss) before income taxes ($ in millions)
B3: Year Ended June 30,
B4: 2024 | C4: 2025 | D4: 2026
A5: Segment revenue
A6: Datacenter & Communications | B6: 2631.369 | C6: 3755.164 | D6: 5274.629
A7: Industrial | B7: 2076.319 | C7: 2054.951 | D7: 1843.552
A8: Total segment revenue | B8: 4707.688 | C8: 5810.115 | D8: 7118.181
A9: Intersegment revenue
A10: Datacenter & Communications | B10: 36.504 | C10: 38.584 | D10: 40.735
A11: Industrial | B11: 55.098 | C11: 77.108 | D11: 99.643
A12: Elimination of intersegment revenue | B12: -91.602 | C12: -115.692 | D12: -140.378
A13: Total intersegment revenue | B13: — | C13: — | D13: —
A14: Segment cost of goods sold and operating expenses (1)
A15: Datacenter & Communications | B15: 2167.905 | C15: 2889.961 | D15: 3985.646
A16: Industrial | B16: 1833.711 | C16: 1724.569 | D16: 1520.422
A17: Total segment cost of goods sold and operating expenses | B17: 4001.616 | C17: 4614.53 | D17: 5506.068
A18: Segment profit
A19: Datacenter & Communications | B19: 499.968 | C19: 903.787 | D19: 1329.719
A20: Industrial | B20: 297.706 | C20: 407.49 | D20: 422.773
A21: Total segment profit | B21: 797.674 | C21: 1311.277 | D21: 1752.492
A22: Unallocated Corporate expenses
A23: Corporate and centralized function costs (2) | B23: -179.624 | C23: -274.333 | D23: -296.748
A24: Share-based compensation | B24: -126.895 | C24: -160.972 | D24: -193.804
A25: Restructuring costs (3) | B25: -27.054 | C25: -160.081 | D25: -63.39
A26: Impairment of assets held-for-sale | B26: — | C26: -84.988 | D26: -64.404
A27: Integration, site consolidation and other costs (4) | B27: -79.82 | C27: -38.237 | D27: -80.084
A28: Amortization of intangibles | B28: -288.16 | C28: -302.788 | D28: -280.334
A29: Interest expense | B29: -288.475 | C29: -243.251 | D29: -190.267
A30: Gain on sale of business | B30: — | C30: — | D30: 124.133
A31: Other income, net | B31: 44.707 | C31: 47.554 | D31: 140.139
A32: Earnings (loss) before income taxes | B32: -147.647 | C32: 94.181 | D32: 847.733
A34: (1) The significant expense category amount aligns with the segment-level information that is regularly provided to the CODM. Segment cost of goods sold and operating expenses primarily include manufacturing costs, labor and research and development costs, and exclude expenses and credits that are included in the Unallocated corporate expenses category.
A35: (2) We do not allocate corporate and centralized function costs that are not directly attributable to our operating segments.
A36: (3) See Note 12. Restructuring Plans for further information.
A37: (4) Integration, site consolidation and other costs are $80 million and $38 million in the years ended June 30, 2026 and June 30, 2025, respectively, and primarily consist of consulting and legal costs related to initiatives to integrate recent acquisitions into common technology systems, to divest businesses and simplify legal entity structure. Integration and site consolidation costs in the year ended June 30, 2024 primarily include consulting costs related to initiatives to integrate recent acquisitions into common technology systems and simplify legal entity structure, and employee severance and retention and other costs related to sites being shut down as part of our 2023 Restructuring Plan or Synergy and Site Consolidation Plan.
A39: Fonte: Coherent Corp., Form 10-K FY2026 (SEC EDGAR) - https://www.sec.gov/Archives/edgar/data/820318/000082031826000020/iivi-20260630.htm

Sheet Note 20 - D&A by Segment
A1: Note 20. Segment and Geographic Reporting - Depreciation and amortization by segment ($ in millions)
B3: Year Ended June 30,
A4: Depreciation and amortization | B4: 2024 | C4: 2025 | D4: 2026
A5: Datacenter & Communications | B5: 213.693 | C5: 209.293 | D5: 212.56
A6: Industrial | B6: 340.601 | C6: 339.377 | D6: 304.96
A7: Corporate and shared services | B7: 5.467 | C7: 4.928 | D7: 4.375
A8: Total depreciation and amortization | B8: 559.761 | C8: 553.598 | D8: 521.895
A11: Fonte: Coherent Corp., Form 10-K FY2026 (SEC EDGAR) - https://www.sec.gov/Archives/edgar/data/820318/000082031826000020/iivi-20260630.htm
